Workbook

Sheet 比較モード
B2: 解析モード | C2: 2 | E2: 解析範囲 | F2: α(degree) | G2: 0 | H2: ~ | I2: 10 | N2: ステップ | O2: 0.1
B3: 1:v 2:α | F3: v(m/s) | G3: 8 | H3: ~ | I3: 14 | O3: 0.5
B5: 機速/翼根迎角 | C5: 翼根迎角/機速 | D5: 主翼形状抵抗 | E5: 主翼翼効率 | F5: 主翼誘導抵抗 | G5: 主翼総抵抗 | H5: 必要推力(全機抗力+5N) | I5: Power
F6: =BASE!$F$9^2/(E6*PI()*BASE!$N$8/2*BASE!$F$4*BASE!$Q$13*2*B6^2) -> #DIV/0! | G6: =F6+D6 -> #DIV/0! | H6: =(G6+BASE!$I$4+BASE!$I$5+BASE!$I$6) -> #DIV/0! | I6: =H6*B6/BASE!$I$7/BASE!$I$8 -> #DIV/0!
F7: =BASE!$F$9^2/(E7*PI()*BASE!$N$8/2*BASE!$F$4*BASE!$Q$13*2*B7^2) -> #DIV/0! | G7: =F7+D7 -> #DIV/0! | H7: =(G7+BASE!$I$4+BASE!$I$5+BASE!$I$6) -> #DIV/0! | I7: =H7*B7/BASE!$I$7/BASE!$I$8 -> #DIV/0!
F8: =BASE!$F$9^2/(E8*PI()*BASE!$N$8/2*BASE!$F$4*BASE!$Q$13*2*B8^2) -> #DIV/0! | G8: =F8+D8 -> #DIV/0! | H8: =(G8+BASE!$I$4+BASE!$I$5+BASE!$I$6) -> #DIV/0! | I8: =H8*B8/BASE!$I$7/BASE!$I$8 -> #DIV/0!
F9: =BASE!$F$9^2/(E9*PI()*BASE!$N$8/2*BASE!$F$4*BASE!$Q$13*2*B9^2) -> #DIV/0! | G9: =F9+D9 -> #DIV/0! | H9: =(G9+BASE!$I$4+BASE!$I$5+BASE!$I$6) -> #DIV/0! | I9: =H9*B9/BASE!$I$7/BASE!$I$8 -> #DIV/0!
F10: =BASE!$F$9^2/(E10*PI()*BASE!$N$8/2*BASE!$F$4*BASE!$Q$13*2*B10^2) -> #DIV/0! | G10: =F10+D10 -> #DIV/0! | H10: =(G10+BASE!$I$4+BASE!$I$5+BASE!$I$6) -> #DIV/0! | I10: =H10*B10/BASE!$I$7/BASE!$I$8 -> #DIV/0!
F11: =BASE!$F$9^2/(E11*PI()*BASE!$N$8/2*BASE!$F$4*BASE!$Q$13*2*B11^2) -> #DIV/0! | G11: =F11+D11 -> #DIV/0! | H11: =(G11+BASE!$I$4+BASE!$I$5+BASE!$I$6) -> #DIV/0! | I11: =H11*B11/BASE!$I$7/BASE!$I$8 -> #DIV/0!
F12: =BASE!$F$9^2/(E12*PI()*BASE!$N$8/2*BASE!$F$4*BASE!$Q$13*2*B12^2) -> #DIV/0! | G12: =F12+D12 -> #DIV/0! | H12: =(G12+BASE!$I$4+BASE!$I$5+BASE!$I$6) -> #DIV/0! | I12: =H12*B12/BASE!$I$7/BASE!$I$8 -> #DIV/0!
F13: =BASE!$F$9^2/(E13*PI()*BASE!$N$8/2*BASE!$F$4*BASE!$Q$13*2*B13^2) -> #DIV/0! | G13: =F13+D13 -> #DIV/0! | H13: =(G13+BASE!$I$4+BASE!$I$5+BASE!$I$6) -> #DIV/0! | I13: =H13*B13/BASE!$I$7/BASE!$I$8 -> #DIV/0!
F14: =BASE!$F$9^2/(E14*PI()*BASE!$N$8/2*BASE!$F$4*BASE!$Q$13*2*B14^2) -> #DIV/0! | G14: =F14+D14 -> #DIV/0! | H14: =(G14+BASE!$I$4+BASE!$I$5+BASE!$I$6) -> #DIV/0! | I14: =H14*B14/BASE!$I$7/BASE!$I$8 -> #DIV/0!
F15: =BASE!$F$9^2/(E15*PI()*BASE!$N$8/2*BASE!$F$4*BASE!$Q$13*2*B15^2) -> #DIV/0! | G15: =F15+D15 -> #DIV/0! | H15: =(G15+BASE!$I$4+BASE!$I$5+BASE!$I$6) -> #DIV/0! | I15: =H15*B15/BASE!$I$7/BASE!$I$8 -> #DIV/0!
F16: =BASE!$F$9^2/(E16*PI()*BASE!$N$8/2*BASE!$F$4*BASE!$Q$13*2*B16^2) -> #DIV/0! | G16: =F16+D16 -> #DIV/0! | H16: =(G16+BASE!$I$4+BASE!$I$5+BASE!$I$6) -> #DIV/0! | I16: =H16*B16/BASE!$I$7/BASE!$I$8 -> #DIV/0!
F17: =BASE!$F$9^2/(E17*PI()*BASE!$N$8/2*BASE!$F$4*BASE!$Q$13*2*B17^2) -> #DIV/0! | G17: =F17+D17 -> #DIV/0! | H17: =(G17+BASE!$I$4+BASE!$I$5+BASE!$I$6) -> #DIV/0! | I17: =H17*B17/BASE!$I$7/BASE!$I$8 -> #DIV/0!
... F36: =BASE!$F$9^2/(E36*PI()*BASE!$N$8/2*BASE!$F$4*BASE!$Q$13*2*B36^2) -> #DIV/0! | G36: =F36+D36 -> #DIV/0! | H36: =(G36+BASE!$I$4+BASE!$I$5+BASE!$I$6) -> #DIV/0! | I36: =H36*B36/BASE!$I$7/BASE!$I$8 -> #DIV/0!

Sheet BASE
E2: 定数コーナー | L2: 誘導抗力概算式
E3: 重力加速度 | F3: 9.7974665 | G3: [m/s^2] | P3: 必要ぱわー
E4: 空気密度 | F4: 1.184584 | G4: [N/m^3] | H4: 尾翼抵抗 | I4: 1 | J4: N | L4: 全機揚力係数^2/π・アス比・翼効率 | P4: =定常時揚力分布!M11 -> 322.10431
E5: 定常機速 | F5: 11.61 | G5: [m/s] | H5: フレーム抵抗 | I5: 1
E6: 機体重量 | F6: 35 | G6: [kg] | H6: フェアリング抵抗 | I6: 4
E7: P重量 | F7: 55 | G7: [kg] | H7: 駆動効率 | I7: 0.85 | M7: 翼効率 | N7: 0.99464582
E8: 総重量 | F8: =F6+F7 -> 90 | G8: [kg] | H8: ペラ効率 | I8: 0.87 | M8: AR | N8: =$L$13^2*4/1000000/$Q$13/2 -> 34.038103
E9: 必要揚力 | F9: =F8*F3 -> 881.77199 | G9: [N]
E10: 動粘性係数 ν | F10: 1.5586019e-05 | G10: m^2/s
C12: 翼型 | F12: cord | I12: Re | L12: 区間長さ | M12: 翼根からの距離 | N12: むかえかく(度) | Q12: 翼面積(m^2) | R12: 備考 | S12: 平均空力翼弦長
A13: 合計値とか | L13: =SUM(L14:L18) -> 10900 | Q13: =SUM(Q14:Q19) -> 6.981 | R13: FP
B14: 1 | C14: LXA-1M3GX | D14: ~ | E14: LXA-1M3GX | F14: 700 | G14: ~ | H14: 700 | I14: =$F$5*$F$14/(1000*$F$10) -> 521428.86 | J14: ~ | K14: =$F$5*$H$14/(1000*$F$10) -> 521428.86 | L14: 1500 | M14: =L14 -> 1500 | N14: 3.5 | O14: ~ | P14: 3.5 | Q14: =(F14+H14)/2*L14/1000000 -> 1.05 | R14: FPA | S14: =(F14+H14)/2 -> 700
B15: 2 | C15: LXA-1M3GX | D15: ~ | E15: LXA-1M3GX | F15: 700 | G15: ~ | H15: 700 | I15: =$F$5*$F$15/(1000*$F$10) -> 521428.86 | J15: ~ | K15: =$F$5*$H$15/(1000*$F$10) -> 521428.86 | L15: 2700 | M15: =M14+L15 -> 4200 | N15: 3.5 | O15: ~ | P15: 3.5 | Q15: =(F15+H15)/2*L15/1000000 -> 1.89 | R15: FPA | S15: =(F15+H15)/2 -> 700
B16: 3 | C16: LXA-1M3GX | D16: ~ | E16: LXA-2M6GX | F16: 700 | G16: ~ | H16: 660 | I16: =$F$5*$F$16/(1000*$F$10) -> 521428.86 | J16: ~ | K16: =$F$5*$H$16/(1000*$F$10) -> 491632.92 | L16: 2700 | M16: =M15+L16 -> 6900 | N16: 3.5 | O16: ~ | P16: 3 | Q16: =(F16+H16)/2*L16/1000000 -> 1.836 | R16: FPA | S16: =(F16+H16)/2 -> 680
B17: 4 | C17: LXA-2M6GX | D17: ~ | E17: STL-07 | F17: 660 | G17: ~ | H17: 540 | I17: =$F$5*$F$17/(1000*$F$10) -> 491632.92 | J17: ~ | K17: =$F$5*$H$17/(1000*$F$10) -> 402245.12 | L17: 2500 | M17: =M16+L17 -> 9400 | N17: 3 | O17: ~ | P17: 1.7 | Q17: =(F17+H17)/2*L17/1000000 -> 1.5 | R17: FPA | S17: =(F17+H17)/2 -> 600
B18: 5 | C18: STL-07 | D18: ~ | E18: rev_tip_115_mod | F18: 540 | G18: ~ | H18: 400 | I18: =$F$5*$F$18/(1000*$F$10) -> 402245.12 | J18: ~ | K18: =$F$5*$H$18/(1000*$F$10) -> 297959.35 | L18: 1500 | M18: =M17+L18 -> 10900 | N18: 1.7 | O18: ~ | P18: 1 | Q18: =(F18+H18)/2*L18/1000000 -> 0.705 | R18: A | S18: =(F18+H18)/2 -> 470
B19: 6 | D19: ~ | G19: ~ | I19: =$F$5*$F$19/(1000*$F$10) -> 0 | J19: ~ | K19: =$F$5*$H$19/(1000*$F$10) -> 0 | M19: =M18+L19 -> 10900 | O19: ~ | Q19: =(F19+H19)/2*L19/1000000 -> 0 | S19: =(F19+H19)/2 -> 0
C22: 設計制約
C24: ・ハイエースでの機体輸送に対応(スパン制約2500程度と予想) ・ダイダロス型 ・
E37: 0 | F37: =F38 -> 700
E38: =L14 -> 1500 | F38: =H14 -> 700
E39: =M15 -> 4200 | F39: =H15 -> 700
E40: =M16 -> 6900 | F40: =H16 -> 660
E41: =M17 -> 9400 | F41: =H17 -> 540 | K41: https://youtube。com/playlist？list=PLtl5ylS6jdP6uOxzSJKPnUsvMbkmalfKg&si=yGcgfqDeptw4trVc
E42: =M18 -> 10900 | F42: =H18 -> 400
E43: =M19 -> 10900

Sheet BASE限界
E2: 定数コーナー | L2: 誘導抗力概算式
E3: 重力加速度 | F3: 9.7974665 | G3: [m/s^2] | P3: 必要ぱわー
E4: 空気密度 | F4: 1.184584 | G4: [N/m^3] | H4: 尾翼抵抗 | I4: 1 | J4: N | L4: 全機揚力係数^2/π・アス比・翼効率 | P4: =低速時揚力分布!M11 -> 301.03778
E5: 定常機速 | F5: 9 | G5: [m/s] | H5: フレーム抵抗 | I5: 1
E6: 機体重量 | F6: 35 | G6: [kg] | H6: フェアリング抵抗 | I6: 4
E7: P重量 | F7: 55 | G7: [kg] | H7: 駆動効率 | I7: 0.9 | M7: 翼効率 | N7: 0.97791804
E8: 総重量 | F8: =F6+F7 -> 90 | G8: [kg] | H8: ペラ効率 | I8: 0.85 | M8: AR | N8: =$L$13^2*4/1000000/$Q$13/2 -> 31.049262
E9: 必要揚力 | F9: =F8*F3 -> 881.77199 | G9: [N]
E10: 動粘性係数 ν | F10: 1.5586019e-05 | G10: m^2/s
C12: 翼型 | F12: cord | I12: Re | L12: 区間長さ | M12: 翼根からの距離 | N12: むかえかく(度) | Q12: 翼面積(m^2) | R12: 備考 | S12: 平均空力翼弦長
A13: 合計値とか | L13: =SUM(L14:L18) -> 10900 | Q13: =SUM(Q14:Q19) -> 7.653 | R13: FP
B14: 1 | C14: LXA-1M3GXFP2 | D14: ~ | E14: LXA-1M3GXFP2 | F14: 860 | G14: ~ | H14: 860 | I14: =$F$5*$F$14/(1000*$F$10) -> 496598.91 | J14: ~ | K14: =$F$5*$H$14/(1000*$F$10) -> 496598.91 | L14: 1500 | M14: =L14 -> 1500 | N14: 3.2 | O14: ~ | P14: 3.2 | Q14: =(F14+H14)/2*L14/1000000 -> 1.29 | R14: FPA | S14: =(F14+H14)/2 -> 860
B15: 2 | C15: LXA-1M3GXFP2 | D15: ~ | E15: LXA-1M3GXFP2 | F15: 860 | G15: ~ | H15: 860 | I15: =$F$5*$F$15/(1000*$F$10) -> 496598.91 | J15: ~ | K15: =$F$5*$H$15/(1000*$F$10) -> 496598.91 | L15: 2700 | M15: =M14+L15 -> 4200 | N15: 3.2 | O15: ~ | P15: 3.2 | Q15: =(F15+H15)/2*L15/1000000 -> 2.322 | R15: FPA | S15: =(F15+H15)/2 -> 860
B16: 3 | C16: LXA-1M3GXFP | D16: ~ | E16: LXA-2M6GXFP | F16: 700 | G16: ~ | H16: 660 | I16: =$F$5*$F$16/(1000*$F$10) -> 404208.42 | J16: ~ | K16: =$F$5*$H$16/(1000*$F$10) -> 381110.79 | L16: 2700 | M16: =M15+L16 -> 6900 | N16: 3.2 | O16: ~ | P16: 2.7 | Q16: =(F16+H16)/2*L16/1000000 -> 1.836 | R16: FPA | S16: =(F16+H16)/2 -> 680
B17: 4 | C17: LXA-2M6GXFP | D17: ~ | E17: STL-07FP | F17: 660 | G17: ~ | H17: 540 | I17: =$F$5*$F$17/(1000*$F$10) -> 381110.79 | J17: ~ | K17: =$F$5*$H$17/(1000*$F$10) -> 311817.92 | L17: 2500 | M17: =M16+L17 -> 9400 | N17: 2.7 | O17: ~ | P17: 1 | Q17: =(F17+H17)/2*L17/1000000 -> 1.5 | R17: FPA | S17: =(F17+H17)/2 -> 600
B18: 5 | C18: STL-07FP | D18: ~ | E18: rev_tip_115_modFP | F18: 540 | G18: ~ | H18: 400 | I18: =$F$5*$F$18/(1000*$F$10) -> 311817.92 | J18: ~ | K18: =$F$5*$H$18/(1000*$F$10) -> 230976.24 | L18: 1500 | M18: =M17+L18 -> 10900 | N18: 1 | O18: ~ | P18: 0.5 | Q18: =(F18+H18)/2*L18/1000000 -> 0.705 | R18: A | S18: =(F18+H18)/2 -> 470
B19: 6 | D19: ~ | G19: ~ | I19: =$F$5*$F$19/(1000*$F$10) -> 0 | J19: ~ | K19: =$F$5*$H$19/(1000*$F$10) -> 0 | M19: =M18+L19 -> 10900 | O19: ~ | Q19: =(F19+H19)/2*L19/1000000 -> 0 | S19: =(F19+H19)/2 -> 0
C22: 設計制約
C24: ・ハイエースでの機体輸送に対応(スパン制約2500程度と予想) ・ダイダロス型 ・ | O24: =(F14-H14)/L14*100 -> 0
O25: =(F15-H15)/L15*100 -> 0
O26: =(F16-H16)/L16*100 -> 1.4814815
O27: =(F17-H17)/L17*100 -> 4.8
O28: =(F18-H18)/L18*100 -> 9.3333333
O29: =(F19-H19)/L19*100 -> #DIV/0!
E37: 0 | F37: =F38 -> 860
E38: =L14 -> 1500 | F38: =H14 -> 860
E39: =M15 -> 4200 | F39: =H15 -> 860
E40: =M16 -> 6900 | F40: =H16 -> 660
E41: =M17 -> 9400 | F41: =H17 -> 540 | K41: https://youtube。com/playlist？list=PLtl5ylS6jdP6uOxzSJKPnUsvMbkmalfKg&si=yGcgfqDeptw4trVc
E42: =M18 -> 10900 | F42: =H18 -> 400
E43: =M19 -> 10900

Sheet 定常時揚力分布
B1: 定常時揚力分布 | G1: 水色は消すな！！
L2: 各種パラメータ
B3: cord | C3: 楕円理想 | D3: 誘導迎角 | E3: Cl | F3: Cd | G3: Cm | H3: XCp | I3: 局所揚力 | J3: 形状抵抗 | L3: L初期値 | M3: 881.772
A4: 0 | B4: 700 | C4: =4*$M$3*10^3*100*0.001*SQRT(1-4*A4^2/(BASE!$L$13*BASE!$L$13*4))/(PI()*BASE!$L$13*2) -> 5.150032 | D4: 0.37670808 | E4: 0.91456211 | F4: 0.007511646 | G4: -0.11327671 | H4: 0.36752733 | I4: =1/2*BASE!$F$4*(BASE!$F$5^2)*B4/1000*E4*0.1 -> 5.1110667 | J4: =1/2*BASE!$F$4*(BASE!$F$5^2)*B4/1000*F4*0.1 -> 0.041979132 | L4: 総揚力 | M4: =SUM(I4:I181)*2 -> 887.71535
A5: 100 | B5: 700 | C5: =4*$M$3*10^3*100*0.001*SQRT(1-4*A5^2/(BASE!$L$13*BASE!$L$13*4))/(PI()*BASE!$L$13*2) -> 5.1498153 | D5: 0.37675581 | E5: 0.91455686 | F5: 0.0075116221 | G5: -0.11327676 | H5: 0.36752809 | I5: =1/2*BASE!$F$4*(BASE!$F$5^2)*(B5+B4)/2000*E5*0.1 -> 5.1110374 | J5: =1/2*BASE!$F$4*(BASE!$F$5^2)*(B5+B4)/2000*F5*0.1 -> 0.041978999 | L5: 両翼形状抵抗 | M5: =SUM(J4:J181)*2 -> 7.8696137
A6: 200 | B6: 700 | C6: =4*$M$3*10^3*100*0.001*SQRT(1-4*A6^2/(BASE!$L$13*BASE!$L$13*4))/(PI()*BASE!$L$13*2) -> 5.149165 | D6: 0.37697105 | E6: 0.91453318 | F6: 0.0075115145 | G6: -0.11327697 | H6: 0.36753154 | I6: =1/2*BASE!$F$4*(BASE!$F$5^2)*(B6+B5)/2000*E6*0.1 -> 5.1109051 | J6: =1/2*BASE!$F$4*(BASE!$F$5^2)*(B6+B5)/2000*F6*0.1 -> 0.041978397 | L6: 全機Cl | M6: =$M$4/BASE!$Q$13/BASE!$F$4/BASE!$F$5^2 -> 0.79638998
A7: 300 | B7: 700 | C7: =4*$M$3*10^3*100*0.001*SQRT(1-4*A7^2/(BASE!$L$13*BASE!$L$13*4))/(PI()*BASE!$L$13*2) -> 5.148081 | D7: 0.37733041 | E7: 0.91449365 | F7: 0.0075113348 | G7: -0.11327733 | H7: 0.36753729 | I7: =1/2*BASE!$F$4*(BASE!$F$5^2)*(B7+B6)/2000*E7*0.1 -> 5.1106842 | J7: =1/2*BASE!$F$4*(BASE!$F$5^2)*(B7+B6)/2000*F7*0.1 -> 0.041977393 | L7: AR | M7: =BASE!$N$8 -> 34.038103
A8: 400 | B8: 700 | C8: =4*$M$3*10^3*100*0.001*SQRT(1-4*A8^2/(BASE!$L$13*BASE!$L$13*4))/(PI()*BASE!$L$13*2) -> 5.1465631 | D8: 0.37778633 | E8: 0.9144435 | F8: 0.0075111068 | G8: -0.11327779 | H8: 0.36754458 | I8: =1/2*BASE!$F$4*(BASE!$F$5^2)*(B8+B7)/2000*E8*0.1 -> 5.1104039 | J8: =1/2*BASE!$F$4*(BASE!$F$5^2)*(B8+B7)/2000*F8*0.1 -> 0.041976119 | L8: 全機誘導抵抗 | M8: =$M$6^2/(BASE!$N$8*BASE!$N$7*PI())*BASE!$F$4*BASE!$F$5^2*BASE!$Q$13 -> 6.6468493
A9: 500 | B9: 700 | C9: =4*$M$3*10^3*100*0.001*SQRT(1-4*A9^2/(BASE!$L$13*BASE!$L$13*4))/(PI()*BASE!$L$13*2) -> 5.1446108 | D9: 0.37843795 | E9: 0.91437183 | F9: 0.007510781 | G9: -0.11327844 | H9: 0.36755501 | I9: =1/2*BASE!$F$4*(BASE!$F$5^2)*(B9+B8)/2000*E9*0.1 -> 5.1100033 | J9: =1/2*BASE!$F$4*(BASE!$F$5^2)*(B9+B8)/2000*F9*0.1 -> 0.041974298 | L9: 主翼総合抵抗 | M9: =$M$8+$M$5 -> 14.516463
A10: 600 | B10: 700 | C10: =4*$M$3*10^3*100*0.001*SQRT(1-4*A10^2/(BASE!$L$13*BASE!$L$13*4))/(PI()*BASE!$L$13*2) -> 5.1422237 | D10: 0.37921377 | E10: 0.91428649 | F10: 0.0075103931 | G10: -0.11327921 | H10: 0.36756742 | I10: =1/2*BASE!$F$4*(BASE!$F$5^2)*(B10+B9)/2000*E10*0.1 -> 5.1095264 | J10: =1/2*BASE!$F$4*(BASE!$F$5^2)*(B10+B9)/2000*F10*0.1 -> 0.041972131 | L10: 全機抵抗 | M10: =$M$9+BASE!$I$4+BASE!$I$5+BASE!$I$6 -> 20.516463
A11: 700 | B11: 700 | C11: =4*$M$3*10^3*100*0.001*SQRT(1-4*A11^2/(BASE!$L$13*BASE!$L$13*4))/(PI()*BASE!$L$13*2) -> 5.1394011 | D11: 0.38008949 | E11: 0.91419016 | F11: 0.0075099553 | G11: -0.11328009 | H11: 0.36758143 | I11: =1/2*BASE!$F$4*(BASE!$F$5^2)*(B11+B10)/2000*E11*0.1 -> 5.1089881 | J11: =1/2*BASE!$F$4*(BASE!$F$5^2)*(B11+B10)/2000*F11*0.1 -> 0.041969684 | L11: 必要出力 | M11: =$M$10*BASE!$F$5/BASE!$I$7/BASE!$I$8 -> 322.10431
A12: 800 | B12: 700 | C12: =4*$M$3*10^3*100*0.001*SQRT(1-4*A12^2/(BASE!$L$13*BASE!$L$13*4))/(PI()*BASE!$L$13*2) -> 5.1361423 | D12: 0.38119571 | E12: 0.91406847 | F12: 0.0075094021 | G12: -0.1132812 | H12: 0.36759913 | I12: =1/2*BASE!$F$4*(BASE!$F$5^2)*(B12+B11)/2000*E12*0.1 -> 5.108308 | J12: =1/2*BASE!$F$4*(BASE!$F$5^2)*(B12+B11)/2000*F12*0.1 -> 0.041966593
A13: 900 | B13: 700 | C13: =4*$M$3*10^3*100*0.001*SQRT(1-4*A13^2/(BASE!$L$13*BASE!$L$13*4))/(PI()*BASE!$L$13*2) -> 5.1324465 | D13: 0.38240854 | E13: 0.91393506 | F13: 0.0075087957 | G13: -0.11328241 | H13: 0.36761854 | I13: =1/2*BASE!$F$4*(BASE!$F$5^2)*(B13+B12)/2000*E13*0.1 -> 5.1075624 | J13: =1/2*BASE!$F$4*(BASE!$F$5^2)*(B13+B12)/2000*F13*0.1 -> 0.041963204
A14: 1000 | B14: 700 | C14: =4*$M$3*10^3*100*0.001*SQRT(1-4*A14^2/(BASE!$L$13*BASE!$L$13*4))/(PI()*BASE!$L$13*2) -> 5.1283128 | D14: 0.38375275 | E14: 0.9137872 | F14: 0.0075081236 | G14: -0.11328375 | H14: 0.36764004 | I14: =1/2*BASE!$F$4*(BASE!$F$5^2)*(B14+B13)/2000*E14*0.1 -> 5.1067361 | J14: =1/2*BASE!$F$4*(BASE!$F$5^2)*(B14+B13)/2000*F14*0.1 -> 0.041959448
A15: 1100 | B15: 700 | C15: =4*$M$3*10^3*100*0.001*SQRT(1-4*A15^2/(BASE!$L$13*BASE!$L$13*4))/(PI()*BASE!$L$13*2) -> 5.1237401 | D15: 0.38532003 | E15: 0.9136148 | F15: 0.00750734 | G15: -0.11328532 | H15: 0.36766512 | I15: =1/2*BASE!$F$4*(BASE!$F$5^2)*(B15+B14)/2000*E15*0.1 -> 5.1057726 | J15: =1/2*BASE!$F$4*(BASE!$F$5^2)*(B15+B14)/2000*F15*0.1 -> 0.041955068
A16: 1200 | B16: 700 | C16: =4*$M$3*10^3*100*0.001*SQRT(1-4*A16^2/(BASE!$L$13*BASE!$L$13*4))/(PI()*BASE!$L$13*2) -> 5.1187272 | D16: 0.38700343 | E16: 0.91342962 | F16: 0.0075064983 | G16: -0.113287 | H16: 0.36769205 | I16: =1/2*BASE!$F$4*(BASE!$F$5^2)*(B16+B15)/2000*E16*0.1 -> 5.1047378 | J16: =1/2*BASE!$F$4*(BASE!$F$5^2)*(B16+B15)/2000*F16*0.1 -> 0.041950364
A17: 1300 | B17: 700 | C17: =4*$M$3*10^3*100*0.001*SQRT(1-4*A17^2/(BASE!$L$13*BASE!$L$13*4))/(PI()*BASE!$L$13*2) -> 5.1132728 | D17: 0.38885616 | E17: 0.91322582 | F17: 0.0075055719 | G17: -0.11328886 | H17: 0.3677217 | I17: =1/2*BASE!$F$4*(BASE!$F$5^2)*(B17+B16)/2000*E17*0.1 -> 5.1035988 | J17: =1/2*BASE!$F$4*(BASE!$F$5^2)*(B17+B16)/2000*F17*0.1 -> 0.041945187
A18: 1400 | B18: 700 | C18: =4*$M$3*10^3*100*0.001*SQRT(1-4*A18^2/(BASE!$L$13*BASE!$L$13*4))/(PI()*BASE!$L$13*2) -> 5.1073755 | D18: 0.39092987 | E18: 0.91299771 | F18: 0.0075045351 | G18: -0.11329093 | H18: 0.36775488 | I18: =1/2*BASE!$F$4*(BASE!$F$5^2)*(B18+B17)/2000*E18*0.1 -> 5.102324 | J18: =1/2*BASE!$F$4*(BASE!$F$5^2)*(B18+B17)/2000*F18*0.1 -> 0.041939393
A19: 1500 | B19: 700 | C19: =4*$M$3*10^3*100*0.001*SQRT(1-4*A19^2/(BASE!$L$13*BASE!$L$13*4))/(PI()*BASE!$L$13*2) -> 5.1010338 | D19: 0.39313349 | E19: 0.91275532 | F19: 0.0075034333 | G19: -0.11329313 | H19: 0.36779014 | I19: =1/2*BASE!$F$4*(BASE!$F$5^2)*(B19+B18)/2000*E19*0.1 -> 5.1009694 | J19: =1/2*BASE!$F$4*(BASE!$F$5^2)*(B19+B18)/2000*F19*0.1 -> 0.041933235
A20: 1600 | B20: 700 | C20: =4*$M$3*10^3*100*0.001*SQRT(1-4*A20^2/(BASE!$L$13*BASE!$L$13*4))/(PI()*BASE!$L$13*2) -> 5.094246 | D20: 0.39555344 | E20: 0.91248912 | F20: 0.0075022233 | G20: -0.11329555 | H20: 0.36782886 | I20: =1/2*BASE!$F$4*(BASE!$F$5^2)*(B20+B19)/2000*E20*0.1 -> 5.0994817 | J20: =1/2*BASE!$F$4*(BASE!$F$5^2)*(B20+B19)/2000*F20*0.1 -> 0.041926473
A21: 1700 | B21: 700 | C21: =4*$M$3*10^3*100*0.001*SQRT(1-4*A21^2/(BASE!$L$13*BASE!$L$13*4))/(PI()*BASE!$L$13*2) -> 5.0870103 | D21: 0.39819873 | E21: 0.91219814 | F21: 0.0075009006 | G21: -0.1132982 | H21: 0.36787118 | I21: =1/2*BASE!$F$4*(BASE!$F$5^2)*(B21+B20)/2000*E21*0.1 -> 5.0978556 | J21: =1/2*BASE!$F$4*(BASE!$F$5^2)*(B21+B20)/2000*F21*0.1 -> 0.041919082
A22: 1800 | B22: 700 | C22: =4*$M$3*10^3*100*0.001*SQRT(1-4*A22^2/(BASE!$L$13*BASE!$L$13*4))/(PI()*BASE!$L$13*2) -> 5.0793248 | D22: 0.4009934 | E22: 0.91189222 | F22: 0.0074994536 | G22: -0.1133 | H22: 0.36791689 | I22: =1/2*BASE!$F$4*(BASE!$F$5^2)*(B22+B21)/2000*E22*0.1 -> 5.0961459 | J22: =1/2*BASE!$F$4*(BASE!$F$5^2)*(B22+B21)/2000*F22*0.1 -> 0.041910995
A23: 1900 | B23: 700 | C23: =4*$M$3*10^3*100*0.001*SQRT(1-4*A23^2/(BASE!$L$13*BASE!$L$13*4))/(PI()*BASE!$L$13*2) -> 5.0711875 | D23: 0.40406419 | E23: 0.91155904 | F23: 0.0074977647 | G23: -0.1133 | H23: 0.36796909 | I23: =1/2*BASE!$F$4*(BASE!$F$5^2)*(B23+B22)/2000*E23*0.1 -> 5.0942839 | J23: =1/2*BASE!$F$4*(BASE!$F$5^2)*(B23+B22)/2000*F23*0.1 -> 0.041901556
... A98: 9400 | B98: 540 | C98: =4*$M$3*10^3*100*0.001*SQRT(1-4*A98^2/(BASE!$L$13*BASE!$L$13*4))/(PI()*BASE!$L$13*2) -> 2.6072164 | D98: 0.46628639 | E98: 0.58438553 | F98: 0.0061190799 | G98: -0.099015716 | H98: 0.41797442 | I98: =1/2*BASE!$F$4*(BASE!$F$5^2)*(B98+B97)/2000*E98*0.1 -> 2.5305763 | J98: =1/2*BASE!$F$4*(BASE!$F$5^2)*(B98+B97)/2000*F98*0.1 -> 0.026497574
A99: 9500 | B99: 530.66667 | C99: =4*$M$3*10^3*100*0.001*SQRT(1-4*A99^2/(BASE!$L$13*BASE!$L$13*4))/(PI()*BASE!$L$13*2) -> 2.5250067 | D99: 0.42133755 | E99: 0.57130421 | F99: 0.0061092311 | G99: -0.095881077 | I99: =1/2*BASE!$F$4*(BASE!$F$5^2)*(B99+B98)/2000*E99*0.1 -> 2.4416984 | J99: =1/2*BASE!$F$4*(BASE!$F$5^2)*(B99+B98)/2000*F99*0.1 -> 0.026110257
A100: 9600 | B100: 521.33333 | C100: =4*$M$3*10^3*100*0.001*SQRT(1-4*A100^2/(BASE!$L$13*BASE!$L$13*4))/(PI()*BASE!$L$13*2) -> 2.4391137 | D100: 0.36797712 | E100: 0.55908683 | F100: 0.0061011399 | G100: -0.092725855 | I100: =1/2*BASE!$F$4*(BASE!$F$5^2)*(B100+B99)/2000*E100*0.1 -> 2.3478228 | J100: =1/2*BASE!$F$4*(BASE!$F$5^2)*(B100+B99)/2000*F100*0.1 -> 0.025621056
A101: 9700 | B101: 512 | C101: =4*$M$3*10^3*100*0.001*SQRT(1-4*A101^2/(BASE!$L$13*BASE!$L$13*4))/(PI()*BASE!$L$13*2) -> 2.3491333 | D101: 0.32734811 | E101: 0.54556037 | F101: 0.0060903916 | G101: -0.089601635 | I101: =1/2*BASE!$F$4*(BASE!$F$5^2)*(B101+B100)/2000*E101*0.1 -> 2.2503681 | J101: =1/2*BASE!$F$4*(BASE!$F$5^2)*(B101+B100)/2000*F101*0.1 -> 0.025122102
A102: 9800 | B102: 502.66667 | C102: =4*$M$3*10^3*100*0.001*SQRT(1-4*A102^2/(BASE!$L$13*BASE!$L$13*4))/(PI()*BASE!$L$13*2) -> 2.2545763 | D102: 0.29567718 | E102: 0.53110306 | F102: 0.006077794 | G102: -0.086498214 | I102: =1/2*BASE!$F$4*(BASE!$F$5^2)*(B102+B101)/2000*E102*0.1 -> 2.151159 | J102: =1/2*BASE!$F$4*(BASE!$F$5^2)*(B102+B101)/2000*F102*0.1 -> 0.024617258
A103: 9900 | B103: 493.33333 | C103: =4*$M$3*10^3*100*0.001*SQRT(1-4*A103^2/(BASE!$L$13*BASE!$L$13*4))/(PI()*BASE!$L$13*2) -> 2.1548403 | D103: 0.27307083 | E103: 0.51569311 | F103: 0.0060635566 | G103: -0.083414943 | I103: =1/2*BASE!$F$4*(BASE!$F$5^2)*(B103+B102)/2000*E103*0.1 -> 2.0503168 | J103: =1/2*BASE!$F$4*(BASE!$F$5^2)*(B103+B102)/2000*F103*0.1 -> 0.024107773
A104: 10000 | B104: 484 | C104: =4*$M$3*10^3*100*0.001*SQRT(1-4*A104^2/(BASE!$L$13*BASE!$L$13*4))/(PI()*BASE!$L$13*2) -> 2.0491692 | D104: 0.25953169 | E104: 0.49931215 | F104: 0.0060486377 | G104: -0.080350923 | I104: =1/2*BASE!$F$4*(BASE!$F$5^2)*(B104+B103)/2000*E104*0.1 -> 1.947983 | J104: =1/2*BASE!$F$4*(BASE!$F$5^2)*(B104+B103)/2000*F104*0.1 -> 0.02359775
A105: 10100 | B105: 474.66667 | C105: =4*$M$3*10^3*100*0.001*SQRT(1-4*A105^2/(BASE!$L$13*BASE!$L$13*4))/(PI()*BASE!$L$13*2) -> 1.9365917 | D105: 0.25669945 | E105: 0.48178234 | F105: 0.0060325059 | G105: -0.077308963 | I105: =1/2*BASE!$F$4*(BASE!$F$5^2)*(B105+B104)/2000*E105*0.1 -> 1.8436939 | J105: =1/2*BASE!$F$4*(BASE!$F$5^2)*(B105+B104)/2000*F105*0.1 -> 0.023085309
A106: 10200 | B106: 465.33333 | C106: =4*$M$3*10^3*100*0.001*SQRT(1-4*A106^2/(BASE!$L$13*BASE!$L$13*4))/(PI()*BASE!$L$13*2) -> 1.8158237 | D106: 0.26597494 | E106: 0.46294377 | F106: 0.0060151847 | G106: -0.074270157 | I106: =1/2*BASE!$F$4*(BASE!$F$5^2)*(B106+B105)/2000*E106*0.1 -> 1.7371063 | J106: =1/2*BASE!$F$4*(BASE!$F$5^2)*(B106+B105)/2000*F106*0.1 -> 0.022570809
A107: 10300 | B107: 456 | C107: =4*$M$3*10^3*100*0.001*SQRT(1-4*A107^2/(BASE!$L$13*BASE!$L$13*4))/(PI()*BASE!$L$13*2) -> 1.6851051 | D107: 0.29125758 | E107: 0.44232887 | F107: 0.0059966041 | G107: -0.071230357 | I107: =1/2*BASE!$F$4*(BASE!$F$5^2)*(B107+B106)/2000*E107*0.1 -> 1.6267933 | J107: =1/2*BASE!$F$4*(BASE!$F$5^2)*(B107+B106)/2000*F107*0.1 -> 0.022054259
A108: 10400 | B108: 446.66667 | C108: =4*$M$3*10^3*100*0.001*SQRT(1-4*A108^2/(BASE!$L$13*BASE!$L$13*4))/(PI()*BASE!$L$13*2) -> 1.5419072 | D108: 0.33899245 | E108: 0.4190219 | F108: 0.0059759372 | G108: -0.068169055 | I108: =1/2*BASE!$F$4*(BASE!$F$5^2)*(B108+B107)/2000*E108*0.1 -> 1.5098522 | J108: =1/2*BASE!$F$4*(BASE!$F$5^2)*(B108+B107)/2000*F108*0.1 -> 0.02153296
A109: 10500 | B109: 437.33333 | C109: =4*$M$3*10^3*100*0.001*SQRT(1-4*A109^2/(BASE!$L$13*BASE!$L$13*4))/(PI()*BASE!$L$13*2) -> 1.3823573 | D109: 0.4199739 | E109: 0.39216018 | F109: 0.0059569353 | G109: -0.065207531 | I109: =1/2*BASE!$F$4*(BASE!$F$5^2)*(B109+B108)/2000*E109*0.1 -> 1.3838406 | J109: =1/2*BASE!$F$4*(BASE!$F$5^2)*(B109+B108)/2000*F109*0.1 -> 0.021020617
A110: 10600 | B110: 428 | C110: =4*$M$3*10^3*100*0.001*SQRT(1-4*A110^2/(BASE!$L$13*BASE!$L$13*4))/(PI()*BASE!$L$13*2) -> 1.1999504 | D110: 0.55290299 | E110: 0.35965925 | F110: 0.005932142 | G110: -0.062236387 | I110: =1/2*BASE!$F$4*(BASE!$F$5^2)*(B110+B109)/2000*E110*0.1 -> 1.2423529 | J110: =1/2*BASE!$F$4*(BASE!$F$5^2)*(B110+B109)/2000*F110*0.1 -> 0.0204911
... A113: 10900 | B113: 400 | C113: =4*$M$3*10^3*100*0.001*SQRT(1-4*A113^2/(BASE!$L$13*BASE!$L$13*4))/(PI()*BASE!$L$13*2) -> 0 | D113: 3.1885328 | E113: 0.0599 | F113: 0.00624 | G113: -0.0554 | I113: =1/2*BASE!$F$4*(BASE!$F$5^2)*(B113+B112)/2000*E113*0.1 -> 0.19351942 | J113: =1/2*BASE!$F$4*(BASE!$F$5^2)*(B113+B112)/2000*F113*0.1 -> 0.020159619
A114: 11000 | C114: =4*$M$3*10^3*100*0.001*SQRT(1-4*A114^2/(BASE!$L$13*BASE!$L$13*4))/(PI()*BASE!$L$13*2) -> #NUM! | J114: =1/2*BASE!$F$4*(BASE!$F$5^2)*(B114+B113)/2000*F114*0.1 -> 0
A115: 11100 | C115: =4*$M$3*10^3*100*0.001*SQRT(1-4*A115^2/(BASE!$L$13*BASE!$L$13*4))/(PI()*BASE!$L$13*2) -> #NUM! | J115: =1/2*BASE!$F$4*(BASE!$F$5^2)*(B115+B114)/2000*F115*0.1 -> 0
A116: 11200 | C116: =4*$M$3*10^3*100*0.001*SQRT(1-4*A116^2/(BASE!$L$13*BASE!$L$13*4))/(PI()*BASE!$L$13*2) -> #NUM! | J116: =1/2*BASE!$F$4*(BASE!$F$5^2)*(B116+B115)/2000*F116*0.1 -> 0
...

Sheet 低速時揚力分布
B1: 低速時揚力分布 | G1: 水色は消すな！！
L2: 各種パラメータ
B3: cord | C3: 楕円理想 | D3: 誘導迎角 | E3: Cl | F3: Cd | G3: Cm | H3: XCp | I3: 局所揚力 | J3: 形状抵抗 | L3: L初期値 | M3: 900
A4: 0 | B4: 860 | C4: =4*$M$3*10^3*100*0.001*SQRT(1-4*A4^2/(BASE限界!$L$13*BASE限界!$L$13*4))/(PI()*BASE限界!$L$13*2) -> 5.2564935 | D4: 0.82409785 | E4: 1.3511397 | F4: 0.011782165 | G4: -0.19326508 | H4: 0.38646147 | I4: =1/2*BASE限界!$F$4*(BASE限界!$F$5^2)*B4/1000*E4*0.1 -> 5.5746755 | J4: =1/2*BASE限界!$F$4*(BASE限界!$F$5^2)*B4/1000*F4*0.1 -> 0.048612107 | L4: 総揚力 | M4: =SUM(I4:I181)*2 -> 912.89622
A5: 100 | B5: 860 | C5: =4*$M$3*10^3*100*0.001*SQRT(1-4*A5^2/(BASE限界!$L$13*BASE限界!$L$13*4))/(PI()*BASE限界!$L$13*2) -> 5.2562723 | D5: 0.82436493 | E5: 1.3511279 | F5: 0.011781524 | G5: -0.19326801 | H5: 0.38646547 | I5: =1/2*BASE限界!$F$4*(BASE限界!$F$5^2)*(B5+B4)/2000*E5*0.1 -> 5.574627 | J5: =1/2*BASE限界!$F$4*(BASE限界!$F$5^2)*(B5+B4)/2000*F5*0.1 -> 0.048609462 | L5: 両翼形状抵抗 | M5: =SUM(J4:J181)*2 -> 7.6906863
A6: 200 | B6: 860 | C6: =4*$M$3*10^3*100*0.001*SQRT(1-4*A6^2/(BASE限界!$L$13*BASE限界!$L$13*4))/(PI()*BASE限界!$L$13*2) -> 5.2556086 | D6: 0.82556932 | E6: 1.351075 | F6: 0.011778634 | G6: -0.19328126 | H6: 0.38648354 | I6: =1/2*BASE限界!$F$4*(BASE限界!$F$5^2)*(B6+B5)/2000*E6*0.1 -> 5.5744083 | J6: =1/2*BASE限界!$F$4*(BASE限界!$F$5^2)*(B6+B5)/2000*F6*0.1 -> 0.048597536 | L6: 全機Cl | M6: =$M$4/BASE限界!$Q$13/BASE限界!$F$4/BASE限界!$F$5^2 -> 1.2431937
A7: 300 | B7: 860 | C7: =4*$M$3*10^3*100*0.001*SQRT(1-4*A7^2/(BASE限界!$L$13*BASE限界!$L$13*4))/(PI()*BASE限界!$L$13*2) -> 5.2545022 | D7: 0.82759706 | E7: 1.3509857 | F7: 0.011773767 | G7: -0.19330357 | H7: 0.38651396 | I7: =1/2*BASE限界!$F$4*(BASE限界!$F$5^2)*(B7+B6)/2000*E7*0.1 -> 5.5740402 | J7: =1/2*BASE限界!$F$4*(BASE限界!$F$5^2)*(B7+B6)/2000*F7*0.1 -> 0.048577457 | L7: AR | M7: =BASE限界!$N$8 -> 31.049262
A8: 400 | B8: 860 | C8: =4*$M$3*10^3*100*0.001*SQRT(1-4*A8^2/(BASE限界!$L$13*BASE限界!$L$13*4))/(PI()*BASE限界!$L$13*2) -> 5.2529529 | D8: 0.83018518 | E8: 1.3508719 | F8: 0.011767556 | G8: -0.19333204 | H8: 0.38655278 | I8: =1/2*BASE限界!$F$4*(BASE限界!$F$5^2)*(B8+B7)/2000*E8*0.1 -> 5.5735704 | J8: =1/2*BASE限界!$F$4*(BASE限界!$F$5^2)*(B8+B7)/2000*F8*0.1 -> 0.048551829 | L8: 全機誘導抵抗 | M8: =$M$6^2/(BASE限界!$N$8*BASE限界!$N$7*PI())*BASE限界!$F$4*BASE限界!$F$5^2*BASE限界!$Q$13 -> 11.897525
A9: 500 | B9: 860 | C9: =4*$M$3*10^3*100*0.001*SQRT(1-4*A9^2/(BASE限界!$L$13*BASE限界!$L$13*4))/(PI()*BASE限界!$L$13*2) -> 5.2509603 | D9: 0.83396308 | E9: 1.3507056 | F9: 0.011758489 | G9: -0.19337359 | H9: 0.38660945 | I9: =1/2*BASE限界!$F$4*(BASE限界!$F$5^2)*(B9+B8)/2000*E9*0.1 -> 5.5728845 | J9: =1/2*BASE限界!$F$4*(BASE限界!$F$5^2)*(B9+B8)/2000*F9*0.1 -> 0.04851442 | L9: 主翼総合抵抗 | M9: =$M$8+$M$5 -> 19.588211
A10: 600 | B10: 860 | C10: =4*$M$3*10^3*100*0.001*SQRT(1-4*A10^2/(BASE限界!$L$13*BASE限界!$L$13*4))/(PI()*BASE限界!$L$13*2) -> 5.2485238 | D10: 0.83854768 | E10: 1.3505039 | F10: 0.011747486 | G10: -0.19342402 | H10: 0.38667822 | I10: =1/2*BASE限界!$F$4*(BASE限界!$F$5^2)*(B10+B9)/2000*E10*0.1 -> 5.5720523 | J10: =1/2*BASE限界!$F$4*(BASE限界!$F$5^2)*(B10+B9)/2000*F10*0.1 -> 0.048469022 | L10: 全機抵抗 | M10: =$M$9+BASE限界!$I$4+BASE限界!$I$5+BASE限界!$I$6 -> 25.588211
A11: 700 | B11: 860 | C11: =4*$M$3*10^3*100*0.001*SQRT(1-4*A11^2/(BASE限界!$L$13*BASE限界!$L$13*4))/(PI()*BASE限界!$L$13*2) -> 5.2456428 | D11: 0.84378135 | E11: 1.3502736 | F11: 0.011734925 | G11: -0.19348159 | H11: 0.38675672 | I11: =1/2*BASE限界!$F$4*(BASE限界!$F$5^2)*(B11+B10)/2000*E11*0.1 -> 5.5711021 | J11: =1/2*BASE限界!$F$4*(BASE限界!$F$5^2)*(B11+B10)/2000*F11*0.1 -> 0.048417197 | L11: 必要出力 | M11: =$M$10*BASE限界!$F$5/BASE限界!$I$7/BASE限界!$I$8 -> 301.03778
A12: 800 | B12: 860 | C12: =4*$M$3*10^3*100*0.001*SQRT(1-4*A12^2/(BASE限界!$L$13*BASE限界!$L$13*4))/(PI()*BASE限界!$L$13*2) -> 5.2423167 | D12: 0.8507244 | E12: 1.3499681 | F12: 0.011718261 | G12: -0.19355797 | H12: 0.38686087 | I12: =1/2*BASE限界!$F$4*(BASE限界!$F$5^2)*(B12+B11)/2000*E12*0.1 -> 5.5698417 | J12: =1/2*BASE限界!$F$4*(BASE限界!$F$5^2)*(B12+B11)/2000*F12*0.1 -> 0.048348446
A13: 900 | B13: 860 | C13: =4*$M$3*10^3*100*0.001*SQRT(1-4*A13^2/(BASE限界!$L$13*BASE限界!$L$13*4))/(PI()*BASE限界!$L$13*2) -> 5.2385445 | D13: 0.85856574 | E13: 1.3496231 | F13: 0.011699442 | G13: -0.19364422 | H13: 0.38697849 | I13: =1/2*BASE限界!$F$4*(BASE限界!$F$5^2)*(B13+B12)/2000*E13*0.1 -> 5.5684182 | J13: =1/2*BASE限界!$F$4*(BASE限界!$F$5^2)*(B13+B12)/2000*F13*0.1 -> 0.0482708
A14: 1000 | B14: 860 | C14: =4*$M$3*10^3*100*0.001*SQRT(1-4*A14^2/(BASE限界!$L$13*BASE限界!$L$13*4))/(PI()*BASE限界!$L$13*2) -> 5.2343254 | D14: 0.86751406 | E14: 1.3492294 | F14: 0.011677966 | G14: -0.19374265 | H14: 0.38711271 | I14: =1/2*BASE限界!$F$4*(BASE限界!$F$5^2)*(B14+B13)/2000*E14*0.1 -> 5.5667937 | J14: =1/2*BASE限界!$F$4*(BASE限界!$F$5^2)*(B14+B13)/2000*F14*0.1 -> 0.048182192
A15: 1100 | B15: 860 | C15: =4*$M$3*10^3*100*0.001*SQRT(1-4*A15^2/(BASE限界!$L$13*BASE限界!$L$13*4))/(PI()*BASE限界!$L$13*2) -> 5.2296581 | D15: 0.87883787 | E15: 1.3487311 | F15: 0.011650789 | G15: -0.19386722 | H15: 0.38728257 | I15: =1/2*BASE限界!$F$4*(BASE限界!$F$5^2)*(B15+B14)/2000*E15*0.1 -> 5.564738 | J15: =1/2*BASE限界!$F$4*(BASE限界!$F$5^2)*(B15+B14)/2000*F15*0.1 -> 0.048070062
A16: 1200 | B16: 860 | C16: =4*$M$3*10^3*100*0.001*SQRT(1-4*A16^2/(BASE限界!$L$13*BASE限界!$L$13*4))/(PI()*BASE限界!$L$13*2) -> 5.2245416 | D16: 0.89165622 | E16: 1.3481671 | F16: 0.011620025 | G16: -0.19400822 | H16: 0.38747484 | I16: =1/2*BASE限界!$F$4*(BASE限界!$F$5^2)*(B16+B15)/2000*E16*0.1 -> 5.5624109 | J16: =1/2*BASE限界!$F$4*(BASE限界!$F$5^2)*(B16+B15)/2000*F16*0.1 -> 0.047943132
A17: 1300 | B17: 860 | C17: =4*$M$3*10^3*100*0.001*SQRT(1-4*A17^2/(BASE限界!$L$13*BASE限界!$L$13*4))/(PI()*BASE限界!$L$13*2) -> 5.2189744 | D17: 0.90676017 | E17: 1.3475296 | F17: 0.011584452 | G17: -0.19418788 | H17: 0.3877014 | I17: =1/2*BASE限界!$F$4*(BASE限界!$F$5^2)*(B17+B16)/2000*E17*0.1 -> 5.5597805 | J17: =1/2*BASE限界!$F$4*(BASE限界!$F$5^2)*(B17+B16)/2000*F17*0.1 -> 0.047796359
A18: 1400 | B18: 860 | C18: =4*$M$3*10^3*100*0.001*SQRT(1-4*A18^2/(BASE限界!$L$13*BASE限界!$L$13*4))/(PI()*BASE限界!$L$13*2) -> 5.2129552 | D18: 0.92680119 | E18: 1.346728 | F18: 0.011538357 | G18: -0.19444842 | H18: 0.38800202 | I18: =1/2*BASE限界!$F$4*(BASE限界!$F$5^2)*(B18+B17)/2000*E18*0.1 -> 5.556473 | J18: =1/2*BASE限界!$F$4*(BASE限界!$F$5^2)*(B18+B17)/2000*F18*0.1 -> 0.047606178
A19: 1500 | B19: 860 | C19: =4*$M$3*10^3*100*0.001*SQRT(1-4*A19^2/(BASE限界!$L$13*BASE限界!$L$13*4))/(PI()*BASE限界!$L$13*2) -> 5.2064824 | D19: 0.93890318 | E19: 1.3462439 | F19: 0.011510523 | G19: -0.19460574 | H19: 0.38818355 | I19: =1/2*BASE限界!$F$4*(BASE限界!$F$5^2)*(B19+B18)/2000*E19*0.1 -> 5.5544758 | J19: =1/2*BASE限界!$F$4*(BASE限界!$F$5^2)*(B19+B18)/2000*F19*0.1 -> 0.047491335
A20: 1600 | B20: 857.03704 | C20: =4*$M$3*10^3*100*0.001*SQRT(1-4*A20^2/(BASE限界!$L$13*BASE限界!$L$13*4))/(PI()*BASE限界!$L$13*2) -> 5.1995543 | D20: 0.92472505 | E20: 1.346811 | F20: 0.011543132 | G20: -0.19442143 | H20: 0.38797088 | I20: =1/2*BASE限界!$F$4*(BASE限界!$F$5^2)*(B20+B19)/2000*E20*0.1 -> 5.5472432 | J20: =1/2*BASE限界!$F$4*(BASE限界!$F$5^2)*(B20+B19)/2000*F20*0.1 -> 0.047543837
A21: 1700 | B21: 854.07407 | C21: =4*$M$3*10^3*100*0.001*SQRT(1-4*A21^2/(BASE限界!$L$13*BASE限界!$L$13*4))/(PI()*BASE限界!$L$13*2) -> 5.192169 | D21: 0.90917989 | E21: 1.3474328 | F21: 0.011578886 | G21: -0.19421934 | H21: 0.3877377 | I21: =1/2*BASE限界!$F$4*(BASE限界!$F$5^2)*(B21+B20)/2000*E21*0.1 -> 5.5306505 | J21: =1/2*BASE限界!$F$4*(BASE限界!$F$5^2)*(B21+B20)/2000*F21*0.1 -> 0.047526506
A22: 1800 | B22: 851.11111 | C22: =4*$M$3*10^3*100*0.001*SQRT(1-4*A22^2/(BASE限界!$L$13*BASE限界!$L$13*4))/(PI()*BASE限界!$L$13*2) -> 5.1843247 | D22: 0.89384735 | E22: 1.3480707 | F22: 0.011614766 | G22: -0.19403232 | H22: 0.38750771 | I22: =1/2*BASE限界!$F$4*(BASE限界!$F$5^2)*(B22+B21)/2000*E22*0.1 -> 5.5141061 | J22: =1/2*BASE限界!$F$4*(BASE限界!$F$5^2)*(B22+B21)/2000*F22*0.1 -> 0.047508675
A23: 1900 | B23: 848.14815 | C23: =4*$M$3*10^3*100*0.001*SQRT(1-4*A23^2/(BASE限界!$L$13*BASE限界!$L$13*4))/(PI()*BASE限界!$L$13*2) -> 5.1760192 | D23: 0.881923 | E23: 1.3485954 | F23: 0.011643385 | G23: -0.19390115 | H23: 0.38732885 | I23: =1/2*BASE限界!$F$4*(BASE限界!$F$5^2)*(B23+B22)/2000*E23*0.1 -> 5.4970819 | J23: =1/2*BASE限界!$F$4*(BASE限界!$F$5^2)*(B23+B22)/2000*F23*0.1 -> 0.047460224
... A113: 10900 | B113: 400 | C113: =4*$M$3*10^3*100*0.001*SQRT(1-4*A113^2/(BASE限界!$L$13*BASE限界!$L$13*4))/(PI()*BASE限界!$L$13*2) -> 0 | D113: 8.7668036 | E113: 0.5939 | F113: 0.00632 | G113: -0.1401 | H113: 0.4853 | I113: =1/2*BASE限界!$F$4*(BASE限界!$F$5^2)*(B113+B112)/2000*E113*0.1 -> 1.1530062 | J113: =1/2*BASE限界!$F$4*(BASE限界!$F$5^2)*(B113+B112)/2000*F113*0.1 -> 0.012269741
A114: 11000 | C114: =4*$M$3*10^3*100*0.001*SQRT(1-4*A114^2/(BASE限界!$L$13*BASE限界!$L$13*4))/(PI()*BASE限界!$L$13*2) -> #NUM! | J114: =1/2*BASE限界!$F$4*(BASE限界!$F$5^2)*(B114+B113)/2000*F114*0.1 -> 0
A115: 11100 | C115: =4*$M$3*10^3*100*0.001*SQRT(1-4*A115^2/(BASE限界!$L$13*BASE限界!$L$13*4))/(PI()*BASE限界!$L$13*2) -> #NUM! | J115: =1/2*BASE限界!$F$4*(BASE限界!$F$5^2)*(B115+B114)/2000*F115*0.1 -> 0
A116: 11200 | C116: =4*$M$3*10^3*100*0.001*SQRT(1-4*A116^2/(BASE限界!$L$13*BASE限界!$L$13*4))/(PI()*BASE限界!$L$13*2) -> #NUM! | J116: =1/2*BASE限界!$F$4*(BASE限界!$F$5^2)*(B116+B115)/2000*F116*0.1 -> 0
A117: 11300 | C117: =4*$M$3*10^3*100*0.001*SQRT(1-4*A117^2/(BASE限界!$L$13*BASE限界!$L$13*4))/(PI()*BASE限界!$L$13*2) -> #NUM! | J117: =1/2*BASE限界!$F$4*(BASE限界!$F$5^2)*(B117+B116)/2000*F117*0.1 -> 0
A118: 11400 | C118: =4*$M$3*10^3*100*0.001*SQRT(1-4*A118^2/(BASE限界!$L$13*BASE限界!$L$13*4))/(PI()*BASE限界!$L$13*2) -> #NUM! | J118: =1/2*BASE限界!$F$4*(BASE限界!$F$5^2)*(B118+B117)/2000*F118*0.1 -> 0
A119: 11500 | C119: =4*$M$3*10^3*100*0.001*SQRT(1-4*A119^2/(BASE限界!$L$13*BASE限界!$L$13*4))/(PI()*BASE限界!$L$13*2) -> #NUM! | J119: =1/2*BASE限界!$F$4*(BASE限界!$F$5^2)*(B119+B118)/2000*F119*0.1 -> 0
A120: 11600 | C120: =4*$M$3*10^3*100*0.001*SQRT(1-4*A120^2/(BASE限界!$L$13*BASE限界!$L$13*4))/(PI()*BASE限界!$L$13*2) -> #NUM! | J120: =1/2*BASE限界!$F$4*(BASE限界!$F$5^2)*(B120+B119)/2000*F120*0.1 -> 0
A121: 11700 | C121: =4*$M$3*10^3*100*0.001*SQRT(1-4*A121^2/(BASE限界!$L$13*BASE限界!$L$13*4))/(PI()*BASE限界!$L$13*2) -> #NUM! | J121: =1/2*BASE限界!$F$4*(BASE限界!$F$5^2)*(B121+B120)/2000*F121*0.1 -> 0
A122: 11800 | C122: =4*$M$3*10^3*100*0.001*SQRT(1-4*A122^2/(BASE限界!$L$13*BASE限界!$L$13*4))/(PI()*BASE限界!$L$13*2) -> #NUM! | J122: =1/2*BASE限界!$F$4*(BASE限界!$F$5^2)*(B122+B121)/2000*F122*0.1 -> 0
A123: 11900 | C123: =4*$M$3*10^3*100*0.001*SQRT(1-4*A123^2/(BASE限界!$L$13*BASE限界!$L$13*4))/(PI()*BASE限界!$L$13*2) -> #NUM! | J123: =1/2*BASE限界!$F$4*(BASE限界!$F$5^2)*(B123+B122)/2000*F123*0.1 -> 0
A124: 12000 | C124: =4*$M$3*10^3*100*0.001*SQRT(1-4*A124^2/(BASE限界!$L$13*BASE限界!$L$13*4))/(PI()*BASE限界!$L$13*2) -> #NUM! | J124: =1/2*BASE限界!$F$4*(BASE限界!$F$5^2)*(B124+B123)/2000*F124*0.1 -> 0
A125: 12100 | C125: =4*$M$3*10^3*100*0.001*SQRT(1-4*A125^2/(BASE限界!$L$13*BASE限界!$L$13*4))/(PI()*BASE限界!$L$13*2) -> #NUM! | J125: =1/2*BASE限界!$F$4*(BASE限界!$F$5^2)*(B125+B124)/2000*F125*0.1 -> 0
... A181: 17700 | C181: =4*$M$3*10^3*100*0.001*SQRT(1-4*A181^2/(BASE限界!$L$13*BASE限界!$L$13*4))/(PI()*BASE限界!$L$13*2) -> #NUM! | J181: =1/2*BASE限界!$F$4*(BASE限界!$F$5^2)*(B181+B180)/2000*F181*0.1 -> 0
